/home/adbraimah/miniconda3/envs/cse537/lib/python3.10/site-packages/auto_gptq/nn_modules/triton_utils/kernels.py:411: FutureWarning: `torch.cuda.amp.custom_fwd(args...)` is deprecated. Please use `torch.amp.custom_fwd(args..., device_type='cuda')` instead.
  def forward(ctx, input, qweight, scales, qzeros, g_idx, bits, maxq):
/home/adbraimah/miniconda3/envs/cse537/lib/python3.10/site-packages/auto_gptq/nn_modules/triton_utils/kernels.py:419: FutureWarning: `torch.cuda.amp.custom_bwd(args...)` is deprecated. Please use `torch.amp.custom_bwd(args..., device_type='cuda')` instead.
  def backward(ctx, grad_output):
/home/adbraimah/miniconda3/envs/cse537/lib/python3.10/site-packages/auto_gptq/nn_modules/triton_utils/kernels.py:461: FutureWarning: `torch.cuda.amp.custom_fwd(args...)` is deprecated. Please use `torch.amp.custom_fwd(args..., device_type='cuda')` instead.
  @custom_fwd(cast_inputs=torch.float16)
CUDA extension not installed.
CUDA extension not installed.
Traceback (most recent call last):
  File "/home/adbraimah/miniconda3/envs/cse537/lib/python3.10/site-packages/transformers/utils/hub.py", line 424, in cached_files
    hf_hub_download(
  File "/home/adbraimah/miniconda3/envs/cse537/lib/python3.10/site-packages/huggingface_hub/utils/_validators.py", line 106, in _inner_fn
    validate_repo_id(arg_value)
  File "/home/adbraimah/miniconda3/envs/cse537/lib/python3.10/site-packages/huggingface_hub/utils/_validators.py", line 154, in validate_repo_id
    raise HFValidationError(
huggingface_hub.errors.HFValidationError: Repo id must be in the form 'repo_name' or 'namespace/repo_name': './models/Llama2_65B_GPTQ'. Use `repo_type` argument if needed.

During handling of the above exception, another exception occurred:

Traceback (most recent call last):
  File "/home/adbraimah/cse537/2025Spring_AI_Project/test_infer_Llama2_and_Mixtral.py", line 19, in benchmark_llama2_65b_gptq_2gpu
    tokenizer = AutoTokenizer.from_pretrained(model_name_or_path, use_fast=True)
  File "/home/adbraimah/miniconda3/envs/cse537/lib/python3.10/site-packages/transformers/models/auto/tokenization_auto.py", line 946, in from_pretrained
    tokenizer_config = get_tokenizer_config(pretrained_model_name_or_path, **kwargs)
  File "/home/adbraimah/miniconda3/envs/cse537/lib/python3.10/site-packages/transformers/models/auto/tokenization_auto.py", line 778, in get_tokenizer_config
    resolved_config_file = cached_file(
  File "/home/adbraimah/miniconda3/envs/cse537/lib/python3.10/site-packages/transformers/utils/hub.py", line 266, in cached_file
    file = cached_files(path_or_repo_id=path_or_repo_id, filenames=[filename], **kwargs)
  File "/home/adbraimah/miniconda3/envs/cse537/lib/python3.10/site-packages/transformers/utils/hub.py", line 470, in cached_files
    resolved_files = [
  File "/home/adbraimah/miniconda3/envs/cse537/lib/python3.10/site-packages/transformers/utils/hub.py", line 471, in <listcomp>
    _get_cache_file_to_return(path_or_repo_id, filename, cache_dir, revision) for filename in full_filenames
  File "/home/adbraimah/miniconda3/envs/cse537/lib/python3.10/site-packages/transformers/utils/hub.py", line 134, in _get_cache_file_to_return
    resolved_file = try_to_load_from_cache(path_or_repo_id, full_filename, cache_dir=cache_dir, revision=revision)
  File "/home/adbraimah/miniconda3/envs/cse537/lib/python3.10/site-packages/huggingface_hub/utils/_validators.py", line 106, in _inner_fn
    validate_repo_id(arg_value)
  File "/home/adbraimah/miniconda3/envs/cse537/lib/python3.10/site-packages/huggingface_hub/utils/_validators.py", line 154, in validate_repo_id
    raise HFValidationError(
huggingface_hub.errors.HFValidationError: Repo id must be in the form 'repo_name' or 'namespace/repo_name': './models/Llama2_65B_GPTQ'. Use `repo_type` argument if needed.
Traceback (most recent call last):
  File "/home/adbraimah/miniconda3/envs/cse537/lib/python3.10/site-packages/huggingface_hub/utils/_http.py", line 409, in hf_raise_for_status
    response.raise_for_status()
  File "/home/adbraimah/miniconda3/envs/cse537/lib/python3.10/site-packages/requests/models.py", line 1024, in raise_for_status
    raise HTTPError(http_error_msg, response=self)
requests.exceptions.HTTPError: 403 Client Error: Forbidden for url: https://huggingface.co/mistralai/Mixtral-8x7B-Instruct-v0.1/resolve/main/config.json

The above exception was the direct cause of the following exception:

Traceback (most recent call last):
  File "/home/adbraimah/miniconda3/envs/cse537/lib/python3.10/site-packages/transformers/utils/hub.py", line 424, in cached_files
    hf_hub_download(
  File "/home/adbraimah/miniconda3/envs/cse537/lib/python3.10/site-packages/huggingface_hub/utils/_validators.py", line 114, in _inner_fn
    return fn(*args, **kwargs)
  File "/home/adbraimah/miniconda3/envs/cse537/lib/python3.10/site-packages/huggingface_hub/file_download.py", line 961, in hf_hub_download
    return _hf_hub_download_to_cache_dir(
  File "/home/adbraimah/miniconda3/envs/cse537/lib/python3.10/site-packages/huggingface_hub/file_download.py", line 1068, in _hf_hub_download_to_cache_dir
    _raise_on_head_call_error(head_call_error, force_download, local_files_only)
  File "/home/adbraimah/miniconda3/envs/cse537/lib/python3.10/site-packages/huggingface_hub/file_download.py", line 1596, in _raise_on_head_call_error
    raise head_call_error
  File "/home/adbraimah/miniconda3/envs/cse537/lib/python3.10/site-packages/huggingface_hub/file_download.py", line 1484, in _get_metadata_or_catch_error
    metadata = get_hf_file_metadata(
  File "/home/adbraimah/miniconda3/envs/cse537/lib/python3.10/site-packages/huggingface_hub/utils/_validators.py", line 114, in _inner_fn
    return fn(*args, **kwargs)
  File "/home/adbraimah/miniconda3/envs/cse537/lib/python3.10/site-packages/huggingface_hub/file_download.py", line 1401, in get_hf_file_metadata
    r = _request_wrapper(
  File "/home/adbraimah/miniconda3/envs/cse537/lib/python3.10/site-packages/huggingface_hub/file_download.py", line 285, in _request_wrapper
    response = _request_wrapper(
  File "/home/adbraimah/miniconda3/envs/cse537/lib/python3.10/site-packages/huggingface_hub/file_download.py", line 309, in _request_wrapper
    hf_raise_for_status(response)
  File "/home/adbraimah/miniconda3/envs/cse537/lib/python3.10/site-packages/huggingface_hub/utils/_http.py", line 426, in hf_raise_for_status
    raise _format(GatedRepoError, message, response) from e
huggingface_hub.errors.GatedRepoError: 403 Client Error. (Request ID: Root=1-681a2855-18798ab358f1a7a628e02e95;942cd214-8905-4bb0-89b4-07985f487088)

Cannot access gated repo for url https://huggingface.co/mistralai/Mixtral-8x7B-Instruct-v0.1/resolve/main/config.json.
Access to model mistralai/Mixtral-8x7B-Instruct-v0.1 is restricted and you are not in the authorized list. Visit https://huggingface.co/mistralai/Mixtral-8x7B-Instruct-v0.1 to ask for access.

The above exception was the direct cause of the following exception:

Traceback (most recent call last):
  File "/home/adbraimah/cse537/2025Spring_AI_Project/test_infer_Llama2_and_Mixtral.py", line 78, in benchmark_mixtral_8x7b_4bit_2gpu
    tokenizer = AutoTokenizer.from_pretrained(model_name_or_path, use_fast=True)
  File "/home/adbraimah/miniconda3/envs/cse537/lib/python3.10/site-packages/transformers/models/auto/tokenization_auto.py", line 966, in from_pretrained
    config = AutoConfig.from_pretrained(
  File "/home/adbraimah/miniconda3/envs/cse537/lib/python3.10/site-packages/transformers/models/auto/configuration_auto.py", line 1114, in from_pretrained
    config_dict, unused_kwargs = PretrainedConfig.get_config_dict(pretrained_model_name_or_path, **kwargs)
  File "/home/adbraimah/miniconda3/envs/cse537/lib/python3.10/site-packages/transformers/configuration_utils.py", line 590, in get_config_dict
    config_dict, kwargs = cls._get_config_dict(pretrained_model_name_or_path, **kwargs)
  File "/home/adbraimah/miniconda3/envs/cse537/lib/python3.10/site-packages/transformers/configuration_utils.py", line 649, in _get_config_dict
    resolved_config_file = cached_file(
  File "/home/adbraimah/miniconda3/envs/cse537/lib/python3.10/site-packages/transformers/utils/hub.py", line 266, in cached_file
    file = cached_files(path_or_repo_id=path_or_repo_id, filenames=[filename], **kwargs)
  File "/home/adbraimah/miniconda3/envs/cse537/lib/python3.10/site-packages/transformers/utils/hub.py", line 481, in cached_files
    raise OSError(
OSError: You are trying to access a gated repo.
Make sure to have access to it at https://huggingface.co/mistralai/Mixtral-8x7B-Instruct-v0.1.
403 Client Error. (Request ID: Root=1-681a2855-18798ab358f1a7a628e02e95;942cd214-8905-4bb0-89b4-07985f487088)

Cannot access gated repo for url https://huggingface.co/mistralai/Mixtral-8x7B-Instruct-v0.1/resolve/main/config.json.
Access to model mistralai/Mixtral-8x7B-Instruct-v0.1 is restricted and you are not in the authorized list. Visit https://huggingface.co/mistralai/Mixtral-8x7B-Instruct-v0.1 to ask for access.
